Workbook

Sheet Spryinterior
A1: URL | B1: Content Type | C1: Traffic (%) | D1: Number of Keywords | E1: Traffic | F1: Adwords Positions | G1: Positions with commercial intents in top 20 | H1: Positions with informational intents in top 20 | I1: Positions with navigational intents in top 20 | J1: Positions with transactional intents in top 20 | K1: Positions with unknown intents in top 20 | L1: Traffic with commercial intents in top 20 | M1: Traffic with informational intents in top 20 | N1: Traffic with navigational intents in top 20 | O1: Traffic with transactional intents in top 20 | P1: Traffic with unknown intents in top 20 | Q1: Traffic Change | R1: Answer Engines | S1: Top Keyword | T1: Primary Intent | U1: LLM Prompts | V1: Check ranking trùng top 10 | W1: Note
A2: https://www.spryinterior.com/blogs/news/are-corner-shelves-a-good-idea | B2: Blog | C2: 4.51 | D2: 27 | E2: 986 | F2: 0 | G2: 21 | H2: 9 | I2: 1 | J2: 3 | K2: 0 | L2: 956 | M2: 33 | N2: 0 | O2: 1 | P2: 0 | Q2: 965 | R2: google-ai | S2: corner bookshelf | T2: Commercial | U2: 7 | V2: =VLOOKUP(S2,'Keyword cả 2 web trong top 10'!A:H,8,0) -> #N/A | W2: Top traffic
A3: https://www.spryinterior.com/blogs/news/corner-tree-bookcase-a-stylish-space-saving-solution | B3: Blog | C3: 2.72 | D3: 2 | E3: 596 | F3: 0 | G3: 2 | H3: 0 | I3: 0 | J3: 0 | K3: 0 | L3: 596 | M3: 0 | N3: 0 | O3: 0 | P3: 0 | Q3: 596 | S3: corner bookshelf | T3: Commercial | U3: 0 | V3: =VLOOKUP(S3,'Keyword cả 2 web trong top 10'!A:H,8,0) -> #N/A | W3: Top traffic
A4: https://www.spryinterior.com/blogs/news/tree-branch-corner-shelf | B4: Blog | C4: 2.26 | D4: 8 | E4: 494 | F4: 0 | G4: 7 | H4: 3 | I4: 0 | J4: 0 | K4: 0 | L4: 494 | M4: 6 | N4: 0 | O4: 0 | P4: 0 | Q4: 488 | S4: corner shelf | T4: Commercial | U4: 0 | V4: =VLOOKUP(S4,'Keyword cả 2 web trong top 10'!A:H,8,0) -> #N/A | W4: Top traffic
A5: https://www.spryinterior.com/blogs/news/hanging-shelves-with-command-strips | B5: Blog | C5: 1.63 | D5: 117 | E5: 358 | F5: 0 | G5: 72 | H5: 67 | I5: 1 | J5: 7 | K5: 0 | L5: 265 | M5: 231 | N5: 0 | O5: 7 | P5: 0 | Q5: -25 | R5: google, google-ai, search-gpt | S5: command strip shelf | T5: Commercial | U5: 58 | V5: =VLOOKUP(S5,'Keyword cả 2 web trong top 10'!A:H,8,0) -> #N/A | W5: Top traffic
A6: https://www.spryinterior.com/collections/corner-floating-shelves | B6: Collection | C6: 6.65 | D6: 536 | E6: 1453 | F6: 0 | G6: 203 | H6: 206 | I6: 0 | J6: 56 | K6: 0 | L6: 1146 | M6: 377 | N6: 0 | O6: 81 | P6: 0 | Q6: -103 | R6: google | S6: corner shelf | T6: Informational | U6: 1 | V6: =VLOOKUP(S6,'Keyword cả 2 web trong top 10'!A:H,8,0) -> #N/A | W6: Top traffic
A7: https://www.spryinterior.com/collections/console-tables | B7: Collection | C7: 4.56 | D7: 1173 | E7: 997 | F7: 0 | G7: 172 | H7: 132 | I7: 0 | J7: 23 | K7: 0 | L7: 702 | M7: 328 | N7: 0 | O7: 45 | P7: 0 | Q7: 151 | S7: wooden console table | T7: Commercial | U7: 0 | V7: =VLOOKUP(S7,'Keyword cả 2 web trong top 10'!A:H,8,0) -> #N/A | W7: Top traffic
A8: https://www.spryinterior.com/collections/tree-bookshelves | B8: Collection | C8: 3.94 | D8: 96 | E8: 861 | F8: 0 | G8: 29 | H8: 72 | I8: 1 | J8: 5 | K8: 0 | L8: 313 | M8: 837 | N8: 0 | O8: 30 | P8: 0 | Q8: -884 | S8: tree shaped bookshelf | T8: Informational | U8: 0 | V8: =VLOOKUP(S8,'Keyword cả 2 web trong top 10'!A:H,8,0) -> 1 | W8: Top traffic
A9: https://www.spryinterior.com/collections/tree-coat-racks | B9: Collection | C9: 3.84 | D9: 136 | E9: 841 | F9: 0 | G9: 48 | H9: 45 | I9: 0 | J9: 4 | K9: 0 | L9: 601 | M9: 286 | N9: 0 | O9: 115 | P9: 0 | Q9: 462 | R9: google | S9: coat tree | T9: Commercial | U9: 1 | V9: =VLOOKUP(S9,'Keyword cả 2 web trong top 10'!A:H,8,0) -> #N/A | W9: Top traffic
A10: https://www.spryinterior.com/collections/coat-racks-hangers | B10: Collection | C10: 3.12 | D10: 371 | E10: 682 | F10: 0 | G10: 80 | H10: 55 | I10: 0 | J10: 9 | K10: 0 | L10: 312 | M10: 402 | N10: 0 | O10: 18 | P10: 0 | Q10: -1086 | R10: google | S10: coat rack with coats | T10: Commercial | U10: 1 | V10: =VLOOKUP(S10,'Keyword cả 2 web trong top 10'!A:H,8,0) -> #N/A | W10: Top traffic
A11: https://www.spryinterior.com/collections/table-aquarium | B11: Collection | C11: 2.86 | D11: 127 | E11: 627 | F11: 0 | G11: 52 | H11: 72 | I11: 0 | J11: 15 | K11: 0 | L11: 287 | M11: 431 | N11: 0 | O11: 122 | P11: 0 | Q11: 162 | R11: google-ai | S11: fish coffee table aquarium | T11: Informational | U11: 4 | V11: =VLOOKUP(S11,'Keyword cả 2 web trong top 10'!A:H,8,0) -> #N/A | W11: Top traffic
A12: https://www.spryinterior.com/collections/cat-tree-towers | B12: Collection | C12: 2.21 | D12: 700 | E12: 484 | F12: 0 | G12: 125 | H12: 98 | I12: 0 | J12: 7 | K12: 0 | L12: 320 | M12: 205 | N12: 0 | O12: 5 | P12: 0 | Q12: -139 | S12: tree cat furniture | T12: Commercial | U12: 0 | V12: =VLOOKUP(S12,'Keyword cả 2 web trong top 10'!A:H,8,0) -> #N/A | W12: Top traffic
A13: https://www.spryinterior.com/collections/floating-desks | B13: Collection | C13: 1.71 | D13: 96 | E13: 375 | F13: 0 | G13: 32 | H13: 62 | I13: 0 | J13: 6 | K13: 0 | L13: 195 | M13: 365 | N13: 0 | O13: 13 | P13: 0 | Q13: -334 | R13: google, google-ai, search-gpt | S13: floating desk | T13: Informational | U13: 5 | V13: =VLOOKUP(S13,'Keyword cả 2 web trong top 10'!A:H,8,0) -> 10 | W13: Top traffic
A14: https://www.spryinterior.com/collections/wall-floating-shelves | B14: Collection | C14: 1.07 | D14: 174 | E14: 234 | F14: 0 | G14: 105 | H14: 59 | I14: 0 | J14: 8 | K14: 0 | L14: 88 | M14: 188 | N14: 0 | O14: 33 | P14: 0 | Q14: 69 | R14: google, google-ai | S14: shelves floating wall | T14: Commercial | U14: 2 | V14: =VLOOKUP(S14,'Keyword cả 2 web trong top 10'!A:H,8,0) -> #N/A | W14: Top traffic
A15: https://www.spryinterior.com/collections/mushroom-floating-shelves | B15: Collection | C15: 1.06 | D15: 15 | E15: 232 | F15: 0 | G15: 3 | H15: 13 | I15: 0 | J15: 2 | K15: 0 | L15: 41 | M15: 212 | N15: 0 | O15: 32 | P15: 0 | Q15: -85 | R15: gemini | S15: mushroom shelves | T15: Informational | U15: 1 | V15: =VLOOKUP(S15,'Keyword cả 2 web trong top 10'!A:H,8,0) -> 2 | W15: Top traffic
A16: https://www.spryinterior.com/products/black-tree-branch-bookshelf-wall-mount-mid-century-sinltb079 | B16: Product | C16: 2.18 | D16: 45 | E16: 477 | F16: 0 | G16: 16 | H16: 43 | I16: 0 | J16: 3 | K16: 0 | L16: 62 | M16: 472 | N16: 0 | O16: 4 | P16: 0 | Q16: -146 | S16: tree bookshelf | T16: Informational | U16: 0 | V16: =VLOOKUP(S16,'Keyword cả 2 web trong top 10'!A:H,8,0) -> 3 | W16: Top traffic
A17: https://www.spryinterior.com/products/modern-abstract-wood-wall-art-for-living-room-decor-sithwa018 | B17: Product | C17: 1.56 | D17: 32 | E17: 342 | F17: 0 | G17: 9 | H17: 29 | I17: 0 | J17: 4 | K17: 0 | L17: 34 | M17: 335 | N17: 0 | O17: 3 | P17: 0 | Q17: 37 | S17: wooden wall accessories | T17: Informational | U17: 0 | V17: =VLOOKUP(S17,'Keyword cả 2 web trong top 10'!A:H,8,0) -> #N/A | W17: Top traffic
A18: https://www.spryinterior.com/ | B18: Trang chủ | C18: 3.08 | D18: 46 | E18: 675 | F18: 20 | G18: 7 | H18: 1 | I18: 9 | J18: 0 | K18: 0 | L18: 11 | M18: 0 | N18: 668 | O18: 0 | P18: 0 | Q18: 270 | S18: spry interiors | T18: Navigational | U18: 0 | V18: =VLOOKUP(S18,'Keyword cả 2 web trong top 10'!A:H,8,0) -> #N/A | W18: Top traffic
A19: https://www.spryinterior.com/blogs/news/weatherproof-outdoor-cat-tree | B19: Blog | C19: 0.96 | D19: 43 | E19: 211 | F19: 0 | G19: 40 | H19: 6 | I19: 0 | J19: 0 | K19: 0 | L19: 202 | M19: 19 | N19: 0 | O19: 0 | P19: 0 | Q19: -174 | R19: google, google-ai, search-gpt | S19: outdoor cat tower | T19: Commercial | U19: 7 | V19: =VLOOKUP(S19,'Keyword cả 2 web trong top 10'!A:H,8,0) -> #N/A
A20: https://www.spryinterior.com/collections/record-player-stands | B20: Collection | C20: 0.85 | D20: 338 | E20: 187 | F20: 0 | G20: 96 | H20: 59 | I20: 0 | J20: 16 | K20: 0 | L20: 100 | M20: 51 | N20: 0 | O20: 10 | P20: 0 | Q20: -50 | R20: google, google-ai | S20: corner record player stand | T20: Commercial | U20: 3 | V20: =VLOOKUP(S20,'Keyword cả 2 web trong top 10'!A:H,8,0) -> #N/A
A21: https://www.spryinterior.com/collections/bar-floating-shelves | B21: Collection | C21: 0.83 | D21: 102 | E21: 183 | F21: 0 | G21: 34 | H21: 46 | I21: 0 | J21: 7 | K21: 0 | L21: 91 | M21: 101 | N21: 0 | O21: 28 | P21: 0 | Q21: -32 | S21: bar shelves wall mounted | T21: Informational | U21: 0 | V21: =VLOOKUP(S21,'Keyword cả 2 web trong top 10'!A:H,8,0) -> #N/A
A22: https://www.spryinterior.com/blogs/news/small-corner-sink-unit | B22: Blog | C22: 0.81 | D22: 19 | E22: 179 | F22: 0 | G22: 6 | H22: 2 | I22: 0 | J22: 1 | K22: 0 | L22: 179 | M22: 0 | N22: 0 | O22: 0 | P22: 0 | Q22: 178 | R22: google | S22: corner vanity | T22: Commercial | U22: 1 | V22: =VLOOKUP(S22,'Keyword cả 2 web trong top 10'!A:H,8,0) -> #N/A
A23: https://www.spryinterior.com/products/rustic-arched-wood-frame-for-living-room-entryway-sithach003 | B23: Product | C23: 0.73 | D23: 24 | E23: 160 | F23: 0 | G23: 6 | H23: 21 | I23: 0 | J23: 1 | K23: 0 | L23: 16 | M23: 160 | N23: 0 | O23: 1 | P23: 0 | Q23: -4 | S23: arch with wood | T23: Informational | U23: 0 | V23: =VLOOKUP(S23,'Keyword cả 2 web trong top 10'!A:H,8,0) -> #N/A
A24: https://www.spryinterior.com/products/rustic-wall-decor-and-large-wooden-art-for-living-room-and-bedroom-decor-sithtvc001 | B24: Product | C24: 0.69 | D24: 38 | E24: 151 | F24: 0 | G24: 22 | H24: 27 | I24: 0 | J24: 0 | K24: 0 | L24: 73 | M24: 117 | N24: 0 | O24: 0 | P24: 0 | Q24: -24 | S24: rustic wall art | T24: Informational | U24: 0 | V24: =VLOOKUP(S24,'Keyword cả 2 web trong top 10'!A:H,8,0) -> #N/A
A25: https://www.spryinterior.com/blogs/news/how-to-hang-coat-rack-on-wall | B25: Blog | C25: 0.67 | D25: 90 | E25: 148 | F25: 0 | G25: 36 | H25: 37 | I25: 0 | J25: 7 | K25: 0 | L25: 128 | M25: 22 | N25: 0 | O25: 14 | P25: 0 | Q25: 71 | R25: gemini, google, google-ai, search-gpt | S25: wall coat rack | T25: Informational | U25: 31 | V25: =VLOOKUP(S25,'Keyword cả 2 web trong top 10'!A:H,8,0) -> #N/A
A26: https://www.spryinterior.com/blogs/news/how-high-to-hang-coat-rack-on-wall | B26: Blog | C26: 0.67 | D26: 113 | E26: 148 | F26: 0 | G26: 18 | H26: 73 | I26: 0 | J26: 3 | K26: 0 | L26: 25 | M26: 144 | N26: 0 | O26: 2 | P26: 0 | Q26: -123 | R26: google, google-ai, search-gpt | S26: coat hook height | T26: Informational | U26: 23 | V26: =VLOOKUP(S26,'Keyword cả 2 web trong top 10'!A:H,8,0) -> 9
A27: https://www.spryinterior.com/products/reclaimed-wood-entryway-console-table-sildtcs073 | B27: Product | C27: 0.66 | D27: 38 | E27: 146 | F27: 0 | G27: 21 | H27: 20 | I27: 0 | J27: 5 | K27: 0 | L27: 73 | M27: 108 | N27: 0 | O27: 2 | P27: 0 | Q27: -20 | S27: wood entry tables | T27: Commercial | U27: 0 | V27: =VLOOKUP(S27,'Keyword cả 2 web trong top 10'!A:H,8,0) -> #N/A
A28: https://www.spryinterior.com/blogs/news/what-is-the-ideal-bookshelf-shelf-spacing | B28: Blog | C28: 0.61 | D28: 170 | E28: 135 | F28: 0 | G28: 8 | H28: 104 | I28: 0 | J28: 0 | K28: 0 | L28: 7 | M28: 130 | N28: 0 | O28: 0 | P28: 0 | Q28: -1 | R28: google, google-ai | S28: standard bookshelf height | T28: Informational | U28: 47 | V28: =VLOOKUP(S28,'Keyword cả 2 web trong top 10'!A:H,8,0) -> 4
A29: https://www.spryinterior.com/blogs/news/bathroom-vanities-32-inch | B29: Blog | C29: 0.6 | D29: 43 | E29: 132 | F29: 0 | G29: 39 | H29: 3 | I29: 0 | J29: 0 | K29: 0 | L29: 130 | M29: 1 | N29: 0 | O29: 0 | P29: 0 | Q29: -93 | R29: google-ai | S29: 32 inch bathroom vanity | T29: Commercial | U29: 2 | V29: =VLOOKUP(S29,'Keyword cả 2 web trong top 10'!A:H,8,0) -> #N/A
A30: https://www.spryinterior.com/blogs/news/what-is-the-bookshelf-rule | B30: Blog | C30: 0.57 | D30: 55 | E30: 126 | F30: 0 | G30: 27 | H30: 32 | I30: 1 | J30: 10 | K30: 0 | L30: 53 | M30: 89 | N30: 0 | O30: 5 | P30: 0 | Q30: -1691 | R30: google, google-ai | S30: bookcase lighting | T30: Informational | U30: 5 | V30: =VLOOKUP(S30,'Keyword cả 2 web trong top 10'!A:H,8,0) -> #N/A
A31: https://www.spryinterior.com/products/tree-bookshelf-driftwood-branch-wall-mount-sinltb017 | B31: Product | C31: 0.55 | D31: 28 | E31: 121 | F31: 0 | G31: 12 | H31: 26 | I31: 0 | J31: 3 | K31: 0 | L31: 44 | M31: 117 | N31: 0 | O31: 0 | P31: 0 | Q31: 14 | S31: tree shelf | T31: Informational | U31: 0 | V31: =VLOOKUP(S31,'Keyword cả 2 web trong top 10'!A:H,8,0) -> 2
A32: https://www.spryinterior.com/products/rustic-wine-rack-for-furniture-home-bar-wall-design-sildttrwh022 | B32: Product | C32: 0.54 | D32: 34 | E32: 118 | F32: 0 | G32: 22 | H32: 20 | I32: 0 | J32: 2 | K32: 0 | L32: 82 | M32: 100 | N32: 0 | O32: 1 | P32: 0 | Q32: -61 | S32: wall wine holder wood | T32: Commercial | U32: 0 | V32: =VLOOKUP(S32,'Keyword cả 2 web trong top 10'!A:H,8,0) -> #N/A
A33: https://www.spryinterior.com/blogs/news/black-unique-coffee-table | B33: Blog | C33: 0.54 | D33: 6 | E33: 118 | F33: 0 | G33: 3 | H33: 0 | I33: 0 | J33: 0 | K33: 0 | L33: 118 | M33: 0 | N33: 0 | O33: 0 | P33: 0 | Q33: 118 | R33: google-ai | S33: black coffee table | T33: Commercial | U33: 3 | V33: =VLOOKUP(S33,'Keyword cả 2 web trong top 10'!A:H,8,0) -> #N/A
A34: https://www.spryinterior.com/collections/tv-cabinets | B34: Collection | C34: 0.53 | D34: 170 | E34: 117 | F34: 0 | G34: 44 | H34: 14 | I34: 1 | J34: 2 | K34: 0 | L34: 104 | M34: 33 | N34: 0 | O34: 0 | P34: 0 | Q34: 5 | R34: google, google-ai | S34: living room tv console | T34: Commercial | U34: 2 | V34: =VLOOKUP(S34,'Keyword cả 2 web trong top 10'!A:H,8,0) -> #N/A
A35: https://www.spryinterior.com/blogs/news/what-is-the-standard-size-of-a-bookshelf | B35: Blog | C35: 0.53 | D35: 171 | E35: 116 | F35: 0 | G35: 11 | H35: 80 | I35: 0 | J35: 0 | K35: 0 | L35: 66 | M35: 50 | N35: 0 | O35: 0 | P35: 0 | Q35: -91 | R35: gemini, google, google-ai | S35: standard bookshelf | T35: Informational | U35: 23 | V35: =VLOOKUP(S35,'Keyword cả 2 web trong top 10'!A:H,8,0) -> #N/A
A36: https://www.spryinterior.com/blogs/news/whats-the-difference-between-a-tree-branch-and-a-tree-limb | B36: Blog | C36: 0.52 | D36: 20 | E36: 115 | F36: 0 | G36: 0 | H36: 15 | I36: 1 | J36: 0 | K36: 0 | L36: 0 | M36: 115 | N36: 0 | O36: 0 | P36: 0 | Q36: 74 | R36: google, search-gpt | S36: tree limbs | T36: Informational | U36: 10 | V36: =VLOOKUP(S36,'Keyword cả 2 web trong top 10'!A:H,8,0) -> #N/A
A37: https://www.spryinterior.com/blogs/news/natural-floating-wood-shelves | B37: Blog | C37: 0.49 | D37: 19 | E37: 108 | F37: 0 | G37: 8 | H37: 11 | I37: 0 | J37: 3 | K37: 0 | L37: 76 | M37: 32 | N37: 0 | O37: 0 | P37: 0 | Q37: 23 | R37: google, google-ai, search-gpt | S37: natural wood floating shelves | T37: Informational | U37: 3 | V37: =VLOOKUP(S37,'Keyword cả 2 web trong top 10'!A:H,8,0) -> #N/A
A38: https://www.spryinterior.com/blogs/news/what-are-entryway-tables-called | B38: Blog | C38: 0.47 | D38: 56 | E38: 104 | F38: 0 | G38: 34 | H38: 30 | I38: 0 | J38: 3 | K38: 0 | L38: 80 | M38: 52 | N38: 0 | O38: 12 | P38: 0 | Q38: -47 | R38: gemini, google, google-ai | S38: entryway tables | T38: Commercial | U38: 10 | V38: =VLOOKUP(S38,'Keyword cả 2 web trong top 10'!A:H,8,0) -> #N/A
A39: https://www.spryinterior.com/blogs/news/best-cat-furniture-for-large-cats | B39: Blog | C39: 0.46 | D39: 38 | E39: 102 | F39: 0 | G39: 14 | H39: 0 | I39: 0 | J39: 0 | K39: 0 | L39: 98 | M39: 0 | N39: 0 | O39: 0 | P39: 0 | Q39: -23 | R39: google, google-ai | S39: top rated cat furniture | T39: Commercial | U39: 11 | V39: =VLOOKUP(S39,'Keyword cả 2 web trong top 10'!A:H,8,0) -> #N/A
A40: https://www.spryinterior.com/blogs/news/what-is-the-weight-limit-for-a-floating-wall | B40: Blog | C40: 0.43 | D40: 26 | E40: 95 | F40: 0 | G40: 5 | H40: 7 | I40: 0 | J40: 1 | K40: 0 | L40: 64 | M40: 95 | N40: 0 | O40: 0 | P40: 0 | Q40: 37 | R40: google, google-ai | S40: wall storage | T40: Informational | U40: 6 | V40: =VLOOKUP(S40,'Keyword cả 2 web trong top 10'!A:H,8,0) -> #N/A
...

Sheet Ashdeco
A1: URL | B1: Content type | C1: Traffic (%) | D1: Number of Keywords | E1: Traffic | F1: Adwords Positions | G1: Positions with commercial intents in top 20 | H1: Positions with informational intents in top 20 | I1: Positions with navigational intents in top 20 | J1: Positions with transactional intents in top 20 | K1: Positions with unknown intents in top 20 | L1: Traffic with commercial intents in top 20 | M1: Traffic with informational intents in top 20 | N1: Traffic with navigational intents in top 20 | O1: Traffic with transactional intents in top 20 | P1: Traffic with unknown intents in top 20 | Q1: Traffic Change | R1: Answer Engines | S1: Top Keyword | T1: Primary Intent | U1: LLM Prompts | V1: Check ranking trùng top 10
A2: https://ashdeco.com/collections/tree-bookshelf | B2: Collection | C2: 5.39 | D2: 94 | E2: 846 | F2: 0 | G2: 28 | H2: 70 | I2: 0 | J2: 5 | K2: 0 | L2: 162 | M2: 797 | N2: 0 | O2: 8 | P2: 0 | Q2: 489 | R2: gemini, google-ai, search-gpt | S2: tree bookshelf | T2: Informational | U2: 16 | V2: =VLOOKUP(S2,'Keyword cả 2 web trong top 10'!A:G,7,0) -> 1
A3: https://ashdeco.com/collections/corner-floating-shelves | B3: Collection | C3: 1.83 | D3: 144 | E3: 287 | F3: 0 | G3: 60 | H3: 71 | I3: 0 | J3: 15 | K3: 0 | L3: 138 | M3: 162 | N3: 0 | O3: 10 | P3: 0 | Q3: 230 | R3: gemini, google, google-ai, search-gpt | S3: wood for corner shelf | T3: Informational | U3: 11 | V3: =VLOOKUP(S3,'Keyword cả 2 web trong top 10'!A:G,7,0) -> #N/A
A4: https://ashdeco.com/collections/cat-tree-towers | B4: Collection | C4: 3.22 | D4: 151 | E4: 506 | F4: 1 | G4: 77 | H4: 67 | I4: 0 | J4: 3 | K4: 0 | L4: 290 | M4: 335 | N4: 0 | O4: 3 | P4: 0 | Q4: 411 | R4: gemini, google, google-ai, search-gpt | S4: wood cat tree | T4: Commercial | U4: 9 | V4: =VLOOKUP(S4,'Keyword cả 2 web trong top 10'!A:G,7,0) -> #N/A
A5: https://ashdeco.com/collections/coat-racks-hangers | B5: Collection | C5: 3.14 | D5: 115 | E5: 493 | F5: 0 | G5: 56 | H5: 46 | I5: 2 | J5: 9 | K5: 0 | L5: 482 | M5: 35 | N5: 0 | O5: 0 | P5: 0 | Q5: 461 | R5: gemini, google, google-ai, search-gpt | S5: wooden coat rack | T5: Commercial | U5: 20 | V5: =VLOOKUP(S5,'Keyword cả 2 web trong top 10'!A:G,7,0) -> #N/A
A6: https://ashdeco.com/collections/shoe-benches | B6: Collection | C6: 2.46 | D6: 198 | E6: 386 | F6: 0 | G6: 24 | H6: 15 | I6: 0 | J6: 9 | K6: 0 | L6: 344 | M6: 24 | N6: 0 | O6: 8 | P6: 0 | Q6: 365 | R6: gemini, google-ai | S6: shoe storage bench | T6: Commercial | U6: 2 | V6: =VLOOKUP(S6,'Keyword cả 2 web trong top 10'!A:G,7,0) -> #N/A
A7: https://ashdeco.com/blogs/news/complete-guide-to-console-tables | B7: Blog | C7: 3.74 | D7: 135 | E7: 587 | F7: 0 | G7: 97 | H7: 31 | I7: 0 | J7: 0 | K7: 0 | L7: 580 | M7: 8 | N7: 0 | O7: 0 | P7: 0 | Q7: 416 | R7: gemini, google, google-ai, search-gpt | S7: sofa table | T7: Commercial | U7: 76 | V7: =VLOOKUP(S7,'Keyword cả 2 web trong top 10'!A:G,7,0) -> #N/A
A8: https://ashdeco.com/blogs/news/corner-shelf-ideas-small-spaces-apartments | B8: Blog | C8: 3.12 | D8: 11 | E8: 489 | F8: 0 | G8: 9 | H8: 2 | I8: 0 | J8: 0 | K8: 0 | L8: 489 | M8: 0 | N8: 0 | O8: 0 | P8: 0 | Q8: 489 | R8: gemini, google-ai, search-gpt | S8: corner shelf | T8: Commercial | U8: 3 | V8: =VLOOKUP(S8,'Keyword cả 2 web trong top 10'!A:G,7,0) -> #N/A
A9: https://ashdeco.com/blogs/buying-guides/floating-shelf-weight-limit-guide | B9: Blog | C9: 3.09 | D9: 111 | E9: 485 | F9: 0 | G9: 88 | H9: 47 | I9: 0 | J9: 2 | K9: 0 | L9: 356 | M9: 436 | N9: 0 | O9: 0 | P9: 0 | Q9: 250 | R9: gemini, google, google-ai, search-gpt | S9: shelves for wall | T9: Commercial | U9: 19 | V9: =VLOOKUP(S9,'Keyword cả 2 web trong top 10'!A:G,7,0) -> #N/A
A10: https://ashdeco.com/blogs/news/corner-shelf-buying-guide | B10: Blog | C10: 2.6 | D10: 59 | E10: 409 | F10: 0 | G10: 43 | H10: 19 | I10: 2 | J10: 8 | K10: 0 | L10: 407 | M10: 328 | N10: 0 | O10: 1 | P10: 0 | Q10: 221 | R10: gemini, google, google-ai, search-gpt | S10: corner shelves | T10: Commercial | U10: 61 | V10: =VLOOKUP(S10,'Keyword cả 2 web trong top 10'!A:G,7,0) -> #N/A
A11: https://ashdeco.com/blogs/buying-guides/entryway-bench-shoe-storage-guide | B11: Blog | C11: 2.38 | D11: 28 | E11: 373 | F11: 0 | G11: 27 | H11: 2 | I11: 0 | J11: 0 | K11: 0 | L11: 373 | M11: 0 | N11: 0 | O11: 0 | P11: 0 | Q11: 373 | R11: google-ai, search-gpt | S11: shoe storage bench | T11: Commercial | U11: 33 | V11: =VLOOKUP(S11,'Keyword cả 2 web trong top 10'!A:G,7,0) -> #N/A
A12: https://ashdeco.com/blogs/room-ideas/coat-hook-height-where-to-mount-for-every-room-guide | B12: Blog | C12: 2.2 | D12: 136 | E12: 346 | F12: 0 | G12: 25 | H12: 105 | I12: 0 | J12: 3 | K12: 0 | L12: 106 | M12: 278 | N12: 0 | O12: 1 | P12: 0 | Q12: 74 | R12: google, google-ai, search-gpt | S12: coat tree | T12: Informational | U12: 37 | V12: =VLOOKUP(S12,'Keyword cả 2 web trong top 10'!A:G,7,0) -> #N/A
A13: https://ashdeco.com/blogs/news/hall-tree-with-storage-buying-guide | B13: Blog | C13: 1.88 | D13: 20 | E13: 296 | F13: 0 | G13: 10 | H13: 4 | I13: 0 | J13: 0 | K13: 0 | L13: 296 | M13: 0 | N13: 0 | O13: 0 | P13: 0 | Q13: 269 | R13: gemini, google-ai, search-gpt | S13: hall tree | T13: Commercial | U13: 25 | V13: =VLOOKUP(S13,'Keyword cả 2 web trong top 10'!A:G,7,0) -> #N/A
... A28: https://ashdeco.com/blogs/news/tree-shaped-bookshelf-why-it-works | B28: Blog | C28: 1.24 | D28: 5 | E28: 195 | F28: 0 | G28: 0 | H28: 5 | I28: 0 | J28: 0 | K28: 0 | L28: 0 | M28: 195 | N28: 0 | O28: 0 | P28: 0 | Q28: 195 | R28: search-gpt | S28: tree bookcase | T28: Informational | U28: 1 | V28: =VLOOKUP(S28,'Keyword cả 2 web trong top 10'!A:G,7,0) -> 3
A29: https://ashdeco.com/blogs/buying-guides/solid-wood-dining-table-under-1500 | B29: Blog | C29: 1.21 | D29: 5 | E29: 191 | F29: 0 | G29: 4 | H29: 2 | I29: 0 | J29: 1 | K29: 0 | L29: 191 | M29: 118 | N29: 0 | O29: 0 | P29: 0 | Q29: -232 | S29: wood dinning table | T29: Commercial | U29: 0 | V29: =VLOOKUP(S29,'Keyword cả 2 web trong top 10'!A:G,7,0) -> #N/A
A30: https://ashdeco.com/collections/mushroom-floating-shelves | B30: Collection | C30: 1.18 | D30: 10 | E30: 185 | F30: 0 | G30: 3 | H30: 9 | I30: 0 | J30: 1 | K30: 0 | L30: 17 | M30: 176 | N30: 0 | O30: 2 | P30: 0 | Q30: 181 | R30: gemini, google-ai, search-gpt | S30: mushroom shelf | T30: Informational | U30: 7 | V30: =VLOOKUP(S30,'Keyword cả 2 web trong top 10'!A:G,7,0) -> 2
A31: https://ashdeco.com/blogs/news/mushroom-shelf-vs-corner-floating-shelf | B31: Blog | C31: 1.14 | D31: 2 | E31: 180 | F31: 0 | G31: 2 | H31: 0 | I31: 0 | J31: 0 | K31: 0 | L31: 180 | M31: 0 | N31: 0 | O31: 0 | P31: 0 | Q31: 180 | R31: google-ai, search-gpt | S31: corner floating shelves | T31: Commercial | U31: 3 | V31: =VLOOKUP(S31,'Keyword cả 2 web trong top 10'!A:G,7,0) -> #N/A
A32: https://ashdeco.com/blogs/buying-guides/cat-trees-for-large-cats-complete-buyers-guide-ashdeco | B32: Blog | C32: 1.11 | D32: 7 | E32: 175 | F32: 0 | G32: 6 | H32: 0 | I32: 0 | J32: 0 | K32: 0 | L32: 175 | M32: 0 | N32: 0 | O32: 0 | P32: 0 | Q32: 12 | R32: gemini, google, google-ai, search-gpt | S32: cat trees for large cats | T32: Commercial | U32: 25 | V32: =VLOOKUP(S32,'Keyword cả 2 web trong top 10'!A:G,7,0) -> #N/A
A33: https://ashdeco.com/blogs/buying-guides/corner-floating-shelf-measurement-guide | B33: Blog | C33: 1.1 | D33: 9 | E33: 173 | F33: 0 | G33: 8 | H33: 1 | I33: 0 | J33: 0 | K33: 0 | L33: 173 | M33: 0 | N33: 0 | O33: 0 | P33: 0 | Q33: -96 | R33: google-ai, search-gpt | S33: floating corner shelves | T33: Commercial | U33: 4 | V33: =VLOOKUP(S33,'Keyword cả 2 web trong top 10'!A:G,7,0) -> #N/A
A34: https://ashdeco.com/collections/record-player-stands | B34: Collection | C34: 1.07 | D34: 169 | E34: 168 | F34: 0 | G34: 57 | H34: 42 | I34: 0 | J34: 9 | K34: 0 | L34: 124 | M34: 32 | N34: 0 | O34: 1 | P34: 0 | Q34: 142 | R34: search-gpt | S34: record player table | T34: Commercial | U34: 2 | V34: =VLOOKUP(S34,'Keyword cả 2 web trong top 10'!A:G,7,0) -> #N/A
A35: https://ashdeco.com/blogs/room-ideas/floating-shelf-above-bed-ideas | B35: Blog | C35: 1.05 | D35: 44 | E35: 166 | F35: 0 | G35: 33 | H35: 19 | I35: 0 | J35: 3 | K35: 0 | L35: 121 | M35: 69 | N35: 0 | O35: 11 | P35: 0 | Q35: 118 | R35: google, google-ai, search-gpt | S35: floating bed shelf | T35: Commercial | U35: 14 | V35: =VLOOKUP(S35,'Keyword cả 2 web trong top 10'!A:G,7,0) -> #N/A
A36: https://ashdeco.com/blogs/buying-guides/tree-bookshelf-buying-guide | B36: Blog | C36: 1.05 | D36: 5 | E36: 166 | F36: 0 | G36: 0 | H36: 4 | I36: 0 | J36: 0 | K36: 0 | L36: 0 | M36: 166 | N36: 0 | O36: 0 | P36: 0 | Q36: 166 | R36: google-ai | S36: tree bookshelf | T36: Informational | U36: 2 | V36: =VLOOKUP(S36,'Keyword cả 2 web trong top 10'!A:G,7,0) -> 1
A37: https://ashdeco.com/blogs/news/bookshelf-rule-styling-guide | B37: Blog | C37: 1.01 | D37: 100 | E37: 159 | F37: 0 | G37: 44 | H37: 63 | I37: 2 | J37: 8 | K37: 0 | L37: 67 | M37: 97 | N37: 0 | O37: 15 | P37: 0 | Q37: -1047 | R37: gemini, google, google-ai, search-gpt | S37: book shelf decor | T37: Informational | U37: 32 | V37: =VLOOKUP(S37,'Keyword cả 2 web trong top 10'!A:G,7,0) -> #N/A
A38: https://ashdeco.com/blogs/buying-guides/extendable-dining-table-worth-it | B38: Blog | C38: 0.95 | D38: 16 | E38: 149 | F38: 0 | G38: 13 | H38: 5 | I38: 0 | J38: 0 | K38: 0 | L38: 70 | M38: 80 | N38: 0 | O38: 0 | P38: 0 | Q38: -239 | R38: gemini, google-ai, search-gpt | S38: expandable dining table | T38: Commercial | U38: 10 | V38: =VLOOKUP(S38,'Keyword cả 2 web trong top 10'!A:G,7,0) -> #N/A
A39: https://ashdeco.com/blogs/buying-guides/small-bathroom-vanity | B39: Blog | C39: 0.94 | D39: 7 | E39: 148 | F39: 0 | G39: 6 | H39: 1 | I39: 0 | J39: 0 | K39: 0 | L39: 148 | M39: 0 | N39: 0 | O39: 0 | P39: 0 | Q39: 148 | R39: google-ai, search-gpt | S39: small bathroom vanity | T39: Commercial | U39: 4 | V39: =VLOOKUP(S39,'Keyword cả 2 web trong top 10'!A:G,7,0) -> #N/A
A40: https://ashdeco.com/blogs/buying-guides/shoe-bench-buying-guide | B40: Blog | C40: 0.88 | D40: 16 | E40: 138 | F40: 0 | G40: 11 | H40: 4 | I40: 0 | J40: 0 | K40: 0 | L40: 133 | M40: 5 | N40: 0 | O40: 0 | P40: 0 | Q40: -120 | R40: google, google-ai, search-gpt | S40: shoe storage bench | T40: Commercial | U40: 53 | V40: =VLOOKUP(S40,'Keyword cả 2 web trong top 10'!A:G,7,0) -> #N/A
A41: https://ashdeco.com/blogs/news/glowledge-vs-ashdeco-floating-shelf | B41: Blog | C41: 0.84 | D41: 1 | E41: 132 | F41: 0 | G41: 1 | H41: 0 | I41: 0 | J41: 0 | K41: 0 | L41: 132 | M41: 0 | N41: 0 | O41: 0 | P41: 0 | Q41: 0 | R41: search-gpt | S41: glowledge floating shelf | T41: Commercial | U41: 4 | V41: =VLOOKUP(S41,'Keyword cả 2 web trong top 10'!A:G,7,0) -> #N/A
... A51: https://ashdeco.com/blogs/buying-guides/hanger-wall-hanger-types-heights-guide | B51: Blog | C51: 0.65 | D51: 35 | E51: 102 | F51: 0 | G51: 25 | H51: 13 | I51: 0 | J51: 0 | K51: 0 | L51: 100 | M51: 66 | N51: 0 | O51: 0 | P51: 0 | Q51: -17 | R51: gemini, google, google-ai, search-gpt | S51: door hooks | T51: Commercial | U51: 67 | V51: =VLOOKUP(S51,'Keyword cả 2 web trong top 10'!A:G,7,0) -> #N/A
A52: https://ashdeco.com/blogs/buying-guides/floating-shelves-cost | B52: Blog | C52: 0.65 | D52: 3 | E52: 102 | F52: 0 | G52: 2 | H52: 2 | I52: 0 | J52: 0 | K52: 0 | L52: 100 | M52: 101 | N52: 0 | O52: 0 | P52: 0 | Q52: 102 | S52: shelving unit | T52: Commercial, Informational | U52: 0 | V52: =VLOOKUP(S52,'Keyword cả 2 web trong top 10'!A:G,7,0) -> #N/A
A53: https://ashdeco.com/blogs/buying-guides/tree-bookshelf-dimensions | B53: Blog | C53: 0.61 | D53: 2 | E53: 97 | F53: 0 | G53: 0 | H53: 2 | I53: 0 | J53: 0 | K53: 0 | L53: 0 | M53: 97 | N53: 0 | O53: 0 | P53: 0 | Q53: 97 | S53: tree bookshelf | T53: Informational | U53: 0 | V53: =VLOOKUP(S53,'Keyword cả 2 web trong top 10'!A:G,7,0) -> 1
A54: https://ashdeco.com/blogs/room-ideas/rustic-corner-shelf-ideas | B54: Blog | C54: 0.61 | D54: 1 | E54: 96 | F54: 0 | G54: 1 | H54: 0 | I54: 0 | J54: 0 | K54: 0 | L54: 96 | M54: 0 | N54: 0 | O54: 0 | P54: 0 | Q54: 96 | S54: corner floating shelves | T54: Commercial | U54: 0 | V54: =VLOOKUP(S54,'Keyword cả 2 web trong top 10'!A:G,7,0) -> #N/A
A55: https://ashdeco.com/blogs/buying-guides/dining-table-size-guide | B55: Blog | C55: 0.61 | D55: 42 | E55: 96 | F55: 0 | G55: 11 | H55: 22 | I55: 0 | J55: 0 | K55: 0 | L55: 93 | M55: 17 | N55: 0 | O55: 0 | P55: 0 | Q55: 96 | R55: google, search-gpt | S55: small tables | T55: Informational | U55: 2 | V55: =VLOOKUP(S55,'Keyword cả 2 web trong top 10'!A:G,7,0) -> #N/A
A56: https://ashdeco.com/blogs/buying-guides/tree-shaped-bookshelf-kids-room | B56: Blog | C56: 0.61 | D56: 1 | E56: 96 | F56: 0 | G56: 0 | H56: 1 | I56: 0 | J56: 0 | K56: 0 | L56: 0 | M56: 96 | N56: 0 | O56: 0 | P56: 0 | Q56: 96 | R56: gemini, google-ai, search-gpt | S56: tree bookcase | T56: Informational | U56: 27 | V56: =VLOOKUP(S56,'Keyword cả 2 web trong top 10'!A:G,7,0) -> 3
A57: https://ashdeco.com/blogs/wood-knowledge/best-wood-for-closet-shelves | B57: Blog | C57: 0.56 | D57: 59 | E57: 89 | F57: 0 | G57: 45 | H57: 22 | I57: 0 | J57: 0 | K57: 0 | L57: 75 | M57: 32 | N57: 0 | O57: 0 | P57: 0 | Q57: 71 | R57: gemini, google, google-ai, search-gpt | S57: closet wood | T57: Commercial | U57: 118 | V57: =VLOOKUP(S57,'Keyword cả 2 web trong top 10'!A:G,7,0) -> #N/A
A58: https://ashdeco.com/blogs/buying-guides/floating-shelf-under-tv | B58: Blog | C58: 0.56 | D58: 15 | E58: 88 | F58: 0 | G58: 9 | H58: 9 | I58: 0 | J58: 1 | K58: 0 | L58: 85 | M58: 6 | N58: 0 | O58: 0 | P58: 0 | Q58: -122 | R58: google, search-gpt | S58: floating tv shelf | T58: Commercial, Informational | U58: 8 | V58: =VLOOKUP(S58,'Keyword cả 2 web trong top 10'!A:G,7,0) -> #N/A
A59: https://ashdeco.com/blogs/news/floating-desk-ideas | B59: Blog | C59: 0.54 | D59: 13 | E59: 86 | F59: 0 | G59: 7 | H59: 9 | I59: 0 | J59: 0 | K59: 0 | L59: 83 | M59: 84 | N59: 0 | O59: 0 | P59: 0 | Q59: -13 | R59: gemini, google, google-ai, search-gpt | S59: floating desk | T59: Informational | U59: 13 | V59: =VLOOKUP(S59,'Keyword cả 2 web trong top 10'!A:G,7,0) -> 2
A60: https://ashdeco.com/blogs/news/floating-shelf-above-toilet | B60: Blog | C60: 0.54 | D60: 29 | E60: 85 | F60: 0 | G60: 9 | H60: 14 | I60: 2 | J60: 3 | K60: 0 | L60: 79 | M60: 4 | N60: 2 | O60: 3 | P60: 0 | Q60: 85 | R60: google, search-gpt | S60: bathroom shelves over toilet | T60: Informational | U60: 9 | V60: =VLOOKUP(S60,'Keyword cả 2 web trong top 10'!A:G,7,0) -> #N/A
A61: https://ashdeco.com/blogs/news/bathroom-floating-shelves-guide | B61: Blog | C61: 0.51 | D61: 14 | E61: 80 | F61: 0 | G61: 8 | H61: 5 | I61: 0 | J61: 1 | K61: 0 | L61: 79 | M61: 80 | N61: 0 | O61: 0 | P61: 0 | Q61: -39 | R61: gemini, google, google-ai, search-gpt | S61: bathroom floating shelves | T61: Commercial | U61: 28 | V61: =VLOOKUP(S61,'Keyword cả 2 web trong top 10'!A:G,7,0) -> #N/A
A62: https://ashdeco.com/blogs/wood-knowledge/why-solid-wood-furniture-lasts-generations | B62: Blog | C62: 0.5 | D62: 1 | E62: 79 | F62: 0 | G62: 1 | H62: 0 | I62: 0 | J62: 0 | K62: 0 | L62: 79 | M62: 0 | N62: 0 | O62: 0 | P62: 0 | Q62: 79 | S62: solid wood furniture | T62: Commercial | U62: 0 | V62: =VLOOKUP(S62,'Keyword cả 2 web trong top 10'!A:G,7,0) -> #N/A
A63: https://ashdeco.com/collections/floating-desk | B63: Collection | C63: 0.44 | D63: 47 | E63: 70 | F63: 0 | G63: 22 | H63: 35 | I63: 0 | J63: 2 | K63: 0 | L63: 24 | M63: 66 | N63: 0 | O63: 1 | P63: 0 | Q63: 52 | R63: google, search-gpt | S63: floating wall desk | T63: Informational | U63: 5 | V63: =VLOOKUP(S63,'Keyword cả 2 web trong top 10'!A:G,7,0) -> 2
...

Sheet Keyword cả 2 web trong top 10
A1: Keyword | B1: Intents | C1: Volume | D1: Keyword Difficulty | E1: CPC | F1: Competition Density | G1: ashdeco.com | H1: spryinterior.com | I1: ashdeco.com (pages) | J1: spryinterior.com (pages) | K1: Results
A2: condo for large cats | B2: Commercial | C2: 40 | D2: 20 | E2: 0,49 | F2: 1,00 | G2: 6 | H2: 9 | I2: https://ashdeco.com/blogs/buying-guides/best-cat-condo-large-cats-heavy-duty | J2: https://www.spryinterior.com/blogs/news/largest-cat-condo | K2: 189
A3: tree bookshelf measurements | B3: Informational, Transactional | C3: 70 | D3: 10 | E3: 0,00 | F3: 1,00 | G3: 5 | H3: 3 | I3: https://ashdeco.com/blogs/buying-guides/corner-tree-bookshelf-measure-guide | J3: https://www.spryinterior.com/blogs/news/diy-tree-bookshelf-plans-the-most-detailed-instructions | K3: 179
A4: weight limit for floating shelves | B4: Informational | C4: 50 | D4: 4 | E4: 0,86 | F4: 1,00 | G4: 4 | H4: 9 | I4: https://ashdeco.com/blogs/buying-guides/floating-shelf-weight-limit-guide | J4: https://www.spryinterior.com/blogs/news/can-floating-shelves-hold-a-lot-of-weight | K4: 116
A5: how to choose a coat rack | B5: Informational | C5: 70 | D5: 2 | E5: 0,00 | F5: 0,00 | G5: 1 | H5: 7 | I5: https://ashdeco.com/blogs/buying-guides/how-to-choose-coat-rack-2026 | J5: https://www.spryinterior.com/blogs/news/where-to-put-coat-rack | K5: 154
A6: floating shelf height | B6: Informational | C6: 110 | D6: 12 | E6: 0,00 | F6: 0,90 | G6: 4 | H6: 1 | I6: https://ashdeco.com/blogs/buying-guides/kitchen-shelf-spacing-height-guide | J6: https://www.spryinterior.com/blogs/news/what-is-the-rule-for-floating-shelves | K6: 186
A7: floating shelf measurements | B7: Informational | C7: 110 | D7: 20 | E7: 0,52 | F7: 0,93 | G7: 9 | H7: 8 | I7: https://ashdeco.com/blogs/buying-guides/kitchen-shelf-spacing-height-guide | J7: https://www.spryinterior.com/blogs/news/what-is-the-average-depth-of-a-floating-shelf | K7: 10800000
A8: typical shelf height | B8: Informational | C8: 110 | D8: 10 | E8: 0,00 | F8: 0,12 | G8: 3 | H8: 10 | I8: https://ashdeco.com/blogs/buying-guides/kitchen-shelf-spacing-height-guide | J8: https://www.spryinterior.com/blogs/news/what-is-the-ideal-bookshelf-shelf-spacing | K8: 128
A9: floating shelf height from floor | B9: Informational | C9: 90 | D9: 0 | E9: 0,00 | F9: 0,61 | G9: 6 | H9: 1 | I9: https://ashdeco.com/blogs/buying-guides/kitchen-shelf-spacing-height-guide | J9: https://www.spryinterior.com/blogs/news/what-is-the-rule-for-floating-shelves | K9: 140
A10: floating shelf spacing | B10: Informational | C10: 90 | D10: 13 | E10: 0,00 | F10: 0,93 | G10: 3 | H10: 10 | I10: https://ashdeco.com/blogs/buying-guides/kitchen-shelf-spacing-height-guide | J10: https://www.spryinterior.com/blogs/news/what-is-the-rule-for-floating-shelves | K10: 177
A11: floating shelves height | B11: Informational | C11: 90 | D11: 4 | E11: 0,00 | F11: 0,95 | G11: 4 | H11: 2 | I11: https://ashdeco.com/blogs/buying-guides/kitchen-shelf-spacing-height-guide | J11: https://www.spryinterior.com/blogs/news/what-is-the-rule-for-floating-shelves | K11: 182
A12: floating shelves height from floor | B12: Informational | C12: 90 | D12: 2 | E12: 0,00 | F12: 0,61 | G12: 5 | H12: 1 | I12: https://ashdeco.com/blogs/buying-guides/kitchen-shelf-spacing-height-guide | J12: https://www.spryinterior.com/blogs/news/what-is-the-rule-for-floating-shelves | K12: 162
A13: how high to hang floating shelves | B13: Informational | C13: 90 | D13: 13 | E13: 0,00 | F13: 0,06 | G13: 9 | H13: 2 | I13: https://ashdeco.com/blogs/buying-guides/kitchen-shelf-spacing-height-guide | J13: https://www.spryinterior.com/blogs/news/what-is-the-rule-for-floating-shelves | K13: 140
... A336: book tree shelves | B336: Commercial | C336: 260 | D336: 21 | E336: 0,52 | F336: 0,94 | G336: 7 | H336: 2 | I336: https://ashdeco.com/products/wood-tree-bookshelves-handmade-mahogany-floating-book-tree-with-large-shelves | J336: https://www.spryinterior.com/collections/tree-bookshelves | K336: 219

Sheet Collection tree-bookshelf
A1: Keyword | B1: Position | C1: Previous position | D1: Search Volume | E1: Keyword Difficulty | F1: CPC | G1: URL | H1: Traffic | I1: Traffic (%) | J1: Traffic Cost | K1: Competition | L1: Number of Results | M1: Trends | N1: Timestamp | O1: SERP Features by Keyword | P1: Keyword Intents | Q1: Position Type
A2: tree bookshelf | B2: 1 | C2: 3 | D2: 8100 | E2: 30 | F2: 0,52 | G2: https://ashdeco.com/collections/tree-bookshelf | H2: 194 | I2: 22,93 | J2: 100 | K2: 0,94 | L2: 216 | M2: 54, 54, 54, 66, 44, 36, 54, 54, 66, 54, 54, 100 | N2: 25/07/2026 | O2: Image pack, Sitelinks, Reviews, Video, Image, Popular products, Related searches, Short videos, Things to know, Discussions and forums | P2: informational | Q2: Organic
A3: tree branch bookshelf | B3: 1 | C3: 9 | D3: 720 | E3: 18 | F3: 0,47 | G3: https://ashdeco.com/collections/tree-bookshelf | H3: 178 | I3: 21,04 | J3: 83 | K3: 0,5 | L3: 8 | M3: 13, 13, 16, 13, 13, 13, 10, 13, 20, 13, 13, 100 | N3: 27/07/2026 | O3: Image pack, Sitelinks, People also ask, Popular products, Related searches, Discussions and forums | P3: informational | Q3: Organic
A4: tree shelf | B4: 1 | C4: 8 | D4: 1600 | E4: 27 | F4: 0,47 | G4: https://ashdeco.com/collections/tree-bookshelf | H4: 131 | I4: 15,48 | J4: 61 | K4: 1 | L4: 209 | M4: 44, 55, 34, 44, 34, 65, 55, 55, 55, 34, 44, 100 | N4: 22/07/2026 | O4: Image pack, Sitelinks, Video, Image, People also ask, Popular products, Related searches, Short videos | P4: informational | Q4: Organic
A5: tree branch shelves | B5: 1 | C5: 7 | D5: 260 | E5: 25 | F5: 0,38 | G5: https://ashdeco.com/collections/tree-bookshelf | H5: 34 | I5: 4,01 | J5: 12 | K5: 1 | L5: 229 | M5: 23, 9, 23, 19, 23, 23, 29, 36, 54, 44, 54, 100 | N5: 26/07/2026 | O5: Image pack, Sitelinks, Video, Video Carousel, People also ask, Popular products, Related searches, Short videos, Discussions and forums | P5: informational | Q5: Organic
A6: bookshelf tree | B6: 1 | C6: 9 | D6: 390 | E6: 10 | F6: 0,52 | G6: https://ashdeco.com/collections/tree-bookshelf | H6: 31 | I6: 3,66 | J6: 16 | K6: 0,94 | L6: 10 | M6: 7, 13, 3, 1, 8, 10, 1, 1, 0, 0, 1, 80 | N6: 18/07/2026 | O6: Image pack, Sitelinks, People also ask, Popular products, Related searches | P6: informational | Q6: Organic
A7: tree wall bookshelf | B7: 1 | C7: 6 | D7: 320 | E7: 22 | F7: 0,56 | G7: https://ashdeco.com/collections/tree-bookshelf | H7: 26 | I7: 3,07 | J7: 14 | K7: 0,2 | L7: 238 | M7: 2, 3, 3, 5, 3, 8, 10, 7, 8, 4, 3, 100 | N7: 24/07/2026 | O7: Image pack, Sitelinks, Reviews, Video, Popular products, Related searches, Short videos, Discussions and forums | P7: commercial, informational | Q7: Organic
A8: solid wood tree bookshelf | B8: 2 | C8: 2 | D8: 390 | E8: 22 | F8: 0,51 | G8: https://ashdeco.com/collections/tree-bookshelf | H8: 25 | I8: 2,95 | J8: 12 | K8: 0,13 | L8: 228 | M8: 0, 0, 4, 3, 2, 0, 0, 0, 1, 1, 0, 100 | N8: 30/06/2026 | O8: Sitelinks, Video, Video Carousel, Popular products, Related searches | P8: commercial | Q8: Organic
A9: floating tree bookshelf | B9: 2 | C9: 0 | D9: 140 | E9: 21 | F9: 0,42 | G9: https://ashdeco.com/collections/tree-bookshelf | H9: 18 | I9: 2,12 | J9: 7 | K9: 0,07 | L9: 246 | M9: 1, 1, 1, 1, 1, 1, 1, 1, 1, 1, 1, 100 | N9: 13/07/2026 | O9: Image pack, Sitelinks, Video, Image, Video Carousel, Popular products, Related searches, Short videos | P9: informational | Q9: Organic
A10: wooden tree bookcase | B10: 1 | C10: 9 | D10: 260 | E10: 24 | F10: 0,66 | G10: https://ashdeco.com/collections/tree-bookshelf | H10: 16 | I10: 1,89 | J10: 10 | K10: 0,45 | L10: 235 | M10: 15, 19, 19, 54, 36, 23, 23, 23, 19, 12, 19, 100 | N10: 46302 | O10: Sitelinks, Video, Video Carousel, People also ask, Popular products, Related searches, Short videos | P10: commercial | Q10: Organic
A11: tree shelves | B11: 3 | C11: 3 | D11: 210 | E11: 23 | F11: 0,52 | G11: https://ashdeco.com/collections/tree-bookshelf | H11: 13 | I11: 1,53 | J11: 6 | K11: 1 | L11: 214 | M11: 82, 82, 100, 100, 100, 66, 5, 5, 5, 23, 0, 10 | N11: 13/06/2026 | O11: Image pack, Sitelinks, Video, Image, Shopping ads, Popular products, Related searches | P11: commercial, informational | Q11: Organic
A12: wall tree bookshelf | B12: 2 | C12: 3 | D12: 170 | E12: 22 | F12: 0,56 | G12: https://ashdeco.com/collections/tree-bookshelf | H12: 13 | I12: 1,53 | J12: 7 | K12: 0,2 | L12: 261 | M12: 10, 12, 15, 15, 15, 7, 23, 12, 7, 5, 7, 100 | N12: 23/07/2026 | O12: Image pack, Sitelinks, Reviews, Video, Video Carousel, Popular products, Related searches, Short videos | P12: commercial, informational | Q12: Organic
A13: tree branch bookcase | B13: 3 | C13: 7 | D13: 170 | E13: 0 | F13: 0,47 | G13: https://ashdeco.com/collections/tree-bookshelf | H13: 11 | I13: 1,3 | J13: 5 | K13: 0,5 | L13: 9 | M13: 100, 23, 53, 53, 28, 28, 23, 66, 53, 35, 53, 35 | N13: 19/07/2026 | O13: Image pack, Sitelinks, Related searches | P13: informational | Q13: Organic
A14: wood tree bookshelf | B14: 1 | C14: 5 | D14: 140 | E14: 21 | F14: 0,66 | G14: https://ashdeco.com/collections/tree-bookshelf | H14: 11 | I14: 1,3 | J14: 7 | K14: 0,45 | L14: 236 | M14: 9, 9, 15, 19, 23, 23, 6, 6, 15, 9, 12, 100 | N14: 29/07/2026 | O14: Image pack, Sitelinks, Reviews, Video, Popular products, Related searches, Short videos, Discussions and forums | P14: informational | Q14: Organic
A15: wooden tree bookshelf | B15: 3 | C15: 6 | D15: 320 | E15: 22 | F15: 0,66 | G15: https://ashdeco.com/collections/tree-bookshelf | H15: 11 | I15: 1,3 | J15: 7 | K15: 0,45 | L15: 268 | M15: 17, 21, 26, 39, 48, 26, 21, 26, 26, 17, 21, 100 | N15: 22/07/2026 | O15: Image pack, Sitelinks, Reviews, Video, Image, Popular products, Related searches, Short videos | P15: informational | Q15: Organic
A16: tree trunk bookshelf | B16: 1 | C16: 4 | D16: 70 | E16: 9 | F16: 0,51 | G16: https://ashdeco.com/collections/tree-bookshelf | H16: 9 | I16: 1,06 | J16: 4 | K16: 1 | L16: 261 | M16: 19, 26, 19, 34, 26, 26, 19, 26, 26, 7, 42, 42 | N16: 14/07/2026 | O16: Image pack, Sitelinks, Video, Video Carousel, Popular products, Related searches, Short videos | P16: commercial, informational | Q16: Organic
A17: wooden tree shelf | B17: 3 | C17: 3 | D17: 140 | E17: 26 | F17: 0,48 | G17: https://ashdeco.com/collections/tree-bookshelf | H17: 9 | I17: 1,06 | J17: 4 | K17: 1 | L17: 261 | M17: 17, 28, 28, 35, 43, 53, 43, 53, 43, 43, 28, 35 | N17: 19/06/2026 | O17: Image pack, Sitelinks, Video, People also ask, Popular products, Related searches | P17: commercial, informational | Q17: Organic
A18: tree floating shelf | B18: 2 | C18: 8 | D18: 110 | E18: 21 | F18: 0,54 | G18: https://ashdeco.com/collections/tree-bookshelf | H18: 9 | I18: 1,06 | J18: 4 | K18: 1 | L18: 247 | M18: 64, 64, 52, 64, 82, 64, 100, 82, 82, 64, 64, 52 | N18: 46180 | O18: Image pack, Sitelinks, Video, Video Carousel, Popular products, Related searches | P18: commercial, informational | Q18: Organic
A19: wall shelf tree | B19: 2 | C19: 2 | D19: 110 | E19: 21 | F19: 0,51 | G19: https://ashdeco.com/collections/tree-bookshelf | H19: 9 | I19: 1,06 | J19: 4 | K19: 1 | L19: 266 | M19: 53, 26, 26, 19, 53, 15, 34, 100, 34, 65, 34, 19 | N19: 16/06/2026 | O19: Image pack, Sitelinks, Video, Video Carousel, Popular products, Related searches, Short videos | P19: commercial, informational | Q19: Organic
A20: branch bookshelf | B20: 2 | C20: 0 | D20: 90 | E20: 22 | F20: 0,7 | G20: https://ashdeco.com/collections/tree-bookshelf | H20: 7 | I20: 0,82 | J20: 4 | K20: 0,65 | L20: 245 | M20: 42, 26, 34, 26, 26, 26, 26, 26, 34, 26, 26, 100 | N20: 24/07/2026 | O20: Image pack, Sitelinks, Video, Image, Popular products, Related searches, Short videos, Discussions and forums | P20: commercial, informational | Q20: Organic
A21: tree bookcase | B21: 6 | C21: 5 | D21: 4400 | E21: 31 | F21: 0,52 | G21: https://ashdeco.com/collections/tree-bookshelf | H21: 6 | I21: 0,7 | J21: 3 | K21: 0,94 | L21: 212 | M21: 35, 35, 29, 29, 66, 100, 35, 66, 54, 19, 66, 66 | N21: 31/07/2026 | O21: Image pack, Sitelinks, Reviews, Video, Image, People also ask, Popular products, Related searches, Short videos, Things to know, Discussions and forums | P21: informational | Q21: Organic
A22: bookcase tree | B22: 9 | C22: 9 | D22: 720 | E22: 15 | F22: 0,54 | G22: https://ashdeco.com/collections/tree-bookshelf | H22: 6 | I22: 0,7 | J22: 3 | K22: 1 | L22: 211 | M22: 5, 7, 7, 65, 100, 3, 0, 0, 0, 0, 0, 0 | N22: 13/06/2026 | O22: Image pack, Sitelinks, Video, Image, Popular products, Related searches | P22: informational | Q22: Organic
A23: tree book shelf for wall | B23: 4 | C23: 7 | D23: 210 | E23: 20 | F23: 0,4 | G23: https://ashdeco.com/collections/tree-bookshelf | H23: 5 | I23: 0,59 | J23: 2 | K23: 1 | L23: 263 | M23: 22, 22, 43, 29, 18, 29, 43, 54, 54, 43, 43, 100 | N23: 19/07/2026 | O23: Image pack, Sitelinks, Video, Video Carousel, Popular products, Related searches, Short videos | P23: informational, transactional | Q23: Organic
A24: tree bookshelves | B24: 6 | C24: 0 | D24: 590 | E24: 2 | F24: 0,52 | G24: https://ashdeco.com/collections/tree-bookshelf | H24: 5 | I24: 0,59 | J24: 2 | K24: 0,94 | L24: 10 | M24: 34, 16, 11, 24, 2, 24, 30, 24, 0, 34, 34, 7 | N24: 23/07/2026 | O24: Image pack, Sitelinks, People also ask, Popular products, Related searches, Discussions and forums | P24: informational | Q24: Organic
A25: tree book shelf | B25: 3 | C25: 10 | D25: 1000 | E25: 26 | F25: 0,52 | G25: https://ashdeco.com/collections/tree-bookshelf | H25: 5 | I25: 0,59 | J25: 2 | K25: 0,94 | L25: 218 | M25: 16, 16, 16, 18, 13, 13, 35, 18, 24, 8, 13, 29 | N25: 17/07/2026 | O25: Image pack, Sitelinks, Reviews, Video, Image, People also ask, Popular products, Related searches, Short videos, Things to know | P25: informational | Q25: Organic
A26: tree trunk bookcase | B26: 1 | C26: 1 | D26: 70 | E26: 23 | F26: 0,51 | G26: https://ashdeco.com/collections/tree-bookshelf | H26: 5 | I26: 0,59 | J26: 2 | K26: 1 | L26: 257 | M26: 23, 33, 23, 33, 33, 33, 23, 33, 33, 9, 52, 52 | N26: 17/07/2026 | O26: Image pack, Sitelinks, Video, Video Carousel, People also ask, Popular products, Related searches, Short videos | P26: commercial, informational | Q26: Organic
A27: tree shelf wall | B27: 2 | C27: 6 | D27: 140 | E27: 18 | F27: 0,44 | G27: https://ashdeco.com/collections/tree-bookshelf | H27: 4 | I27: 0,47 | J27: 1 | K27: 1 | L27: 216 | M27: 43, 66, 2, 0, 0, 0, 100, 14, 100, 2, 8, 43 | N27: 20/07/2026 | O27: Image pack, Sitelinks, Video, Popular products, Related searches, Short videos | P27: commercial, informational | Q27: Organic
A28: tree wall shelves | B28: 2 | C28: 8 | D28: 110 | E28: 18 | F28: 0,44 | G28: https://ashdeco.com/collections/tree-bookshelf | H28: 4 | I28: 0,47 | J28: 1 | K28: 1 | L28: 235 | M28: 15, 15, 15, 6, 34, 34, 34, 28, 28, 28, 28, 100 | N28: 29/07/2026 | O28: Image pack, Sitelinks, Video, Video Carousel, Popular products, Related searches, Short videos, Discussions and forums | P28: informational | Q28: Organic
A29: trunk bookshelf | B29: 1 | C29: 1 | D29: 50 | E29: 21 | F29: 0 | G29: https://ashdeco.com/collections/tree-bookshelf | H29: 4 | I29: 0,47 | J29: 0 | K29: 0,86 | L29: 215 | M29: 11, 11, 11, 11, 64, 11, 64, 11, 82, 64, 11, 11 | N29: 46362 | O29: Image pack, Sitelinks, Reviews, Video, Image, Popular products, Related searches | P29: commercial, informational | Q29: Organic
A30: wall tree shelf | B30: 5 | C30: 5 | D30: 170 | E30: 21 | F30: 0,51 | G30: https://ashdeco.com/collections/tree-bookshelf | H30: 4 | I30: 0,47 | J30: 2 | K30: 1 | L30: 259 | M30: 53, 53, 43, 35, 17, 53, 66, 66, 43, 43, 23, 35 | N30: 22/06/2026 | O30: Image pack, Sitelinks, Video, Popular products, Related searches, Short videos | P30: informational | Q30: Organic
A31: tree bookshelf for nursery | B31: 3 | C31: 3 | D31: 140 | E31: 13 | F31: 0,53 | G31: https://ashdeco.com/collections/tree-bookshelf | H31: 4 | I31: 0,47 | J31: 2 | K31: 1 | L31: 218 | M31: 21, 21, 28, 28, 53, 43, 43, 53, 53, 81, 43, 65 | N31: 18/06/2026 | O31: Image pack, Sitelinks, Video, Image, Popular products, Related searches | P31: commercial | Q31: Organic
A32: wood tree shelf | B32: 3 | C32: 3 | D32: 90 | E32: 21 | F32: 0,38 | G32: https://ashdeco.com/collections/tree-bookshelf | H32: 3 | I32: 0,35 | J32: 1 | K32: 0,34 | L32: 230 | M32: 0, 5, 6, 4, 6, 4, 6, 5, 6, 5, 6, 100 | N32: 28/06/2026 | O32: Image pack, Sitelinks, Video, Popular products, Related searches, Short videos | P32: informational | Q32: Organic
A33: tree trunk shelves | B33: 2 | C33: 2 | D33: 50 | E33: 20 | F33: 0,39 | G33: https://ashdeco.com/collections/tree-bookshelf | H33: 3 | I33: 0,35 | J33: 1 | K33: 1 | L33: 203 | M33: 78, 78, 14, 14, 14, 14, 14, 78, 14, 78, 14, 14 | N33: 17/06/2026 | O33: Image pack, Sitelinks, Video, Image, Video Carousel, Popular products, Related searches | P33: informational | Q33: Organic
A34: bookshelf that looks like a tree | B34: 4 | C34: 4 | D34: 90 | E34: 20 | F34: 0,37 | G34: https://ashdeco.com/collections/tree-bookshelf | H34: 3 | I34: 0,35 | J34: 1 | K34: 0,76 | L34: 287 | M34: 26, 19, 34, 34, 26, 19, 34, 26, 34, 19, 26, 100 | N34: 46119 | O34: Image pack, Sitelinks, Video, Image, Video Carousel, Popular products, Related searches, Short videos | P34: informational | Q34: Organic
A35: tree wall shelving | B35: 3 | C35: 3 | D35: 70 | E35: 20 | F35: 0,51 | G35: https://ashdeco.com/collections/tree-bookshelf | H35: 3 | I35: 0,35 | J35: 1 | K35: 1 | L35: 233 | M35: 100, 100, 100, 0, 0, 0, 0, 33, 0, 33, 0, 0 | N35: 22/06/2026 | O35: Image pack, Sitelinks, Video, Image, Popular products, Related searches | P35: commercial, informational | Q35: Organic
A36: tree wood shelves | B36: 2 | C36: 6 | D36: 50 | E36: 20 | F36: 0,38 | G36: https://ashdeco.com/collections/tree-bookshelf | H36: 3 | I36: 0,35 | J36: 1 | K36: 0,34 | L36: 202 | M36: 52, 52, 0, 0, 0, 0, 33, 100, 33, 0, 0, 0 | N36: 14/07/2026 | O36: Sitelinks, Video, Video Carousel, Popular products, Related searches, Short videos | P36: commercial | Q36: Organic
A37: tree book.shelf | B37: 2 | C37: 12 | D37: 110 | E37: 24 | F37: 0,52 | G37: https://ashdeco.com/collections/tree-bookshelf | H37: 3 | I37: 0,35 | J37: 1 | K37: 0,94 | L37: 186 | M37: 0, 0, 0, 0, 0, 100, 0, 0, 0, 0, 0, 0 | N37: 46333 | O37: Sitelinks, Video, People also ask, Popular products, Short videos | P37: informational | Q37: Organic
A38: real tree bookshelf | B38: 3 | C38: 6 | D38: 140 | E38: 0 | F38: 0,61 | G38: https://ashdeco.com/collections/tree-bookshelf | H38: 3 | I38: 0,35 | J38: 1 | K38: 1 | L38: 226 | M38: 42, 42, 80, 53, 53, 3, 65, 65, 100, 53, 80, 65 | N38: 13/07/2026 | O38: Image pack, Sitelinks, Video, Image, Video Carousel, People also ask, Popular products, Related searches | P38: informational | Q38: Organic
A39: bookcase tree | B39: 10 | C39: 9 | D39: 720 | E39: 15 | F39: 0,54 | G39: https://ashdeco.com/collections/tree-bookshelf | H39: 3 | I39: 0,35 | J39: 1 | K39: 1 | L39: 211 | M39: 5, 7, 7, 65, 100, 3, 0, 0, 0, 0, 0, 0 | N39: 13/06/2026 | O39: Image pack, Sitelinks, Video, Image, Popular products, Related searches | P39: informational | Q39: Organic
A40: nursery bookshelf tree | B40: 7 | C40: 14 | D40: 140 | E40: 17 | F40: 0,51 | G40: https://ashdeco.com/collections/tree-bookshelf | H40: 2 | I40: 0,23 | J40: 1 | K40: 1 | L40: 10 | M40: 34, 26, 26, 26, 42, 53, 65, 53, 100, 53, 80, 80 | N40: 18/07/2026 | O40: Image pack, Sitelinks, Image, Popular products, Related searches | P40: informational | Q40: Organic
...

Sheet Collection corner-floating-shel
A1: Keyword | B1: Position | C1: Previous position | D1: Search Volume | E1: Keyword Difficulty | F1: CPC | G1: URL | H1: Traffic | I1: Traffic (%) | J1: Traffic Cost | K1: Competition | L1: Number of Results | M1: Trends | N1: Timestamp | O1: SERP Features by Keyword | P1: Keyword Intents | Q1: Position Type
A2: corner shelf | B2: 6 | C2: 10 | D2: 40500 | E2: 45 | F2: 0,42 | G2: https://www.spryinterior.com/collections/corner-floating-shelves | H2: 283 | I2: 19,47 | J2: 118 | K2: 1 | L2: 248 | M2: 54, 44, 54, 81, 54, 44, 54, 54, 66, 44, 44, 44 | N2: ######## | O2: Image pack, Sitelinks, Video, Popular products, Related searches, Things to know | P2: commercial | Q2: Organic
A3: corner shelfs | B3: 3 | C3: 3 | D3: 2900 | E3: 44 | F3: 0,42 | G3: https://www.spryinterior.com/collections/corner-floating-shelves | H3: 188 | I3: 12,93 | J3: 78 | K3: 1 | L3: 254 | M3: 44, 16, 24, 24, 10, 10, 19, 16, 19, 19, 3, 19 | N3: ######## | O3: Image pack, Sitelinks, Reviews, Video, People also ask, Popular products, Related searches, Short videos, Things to know, Discussions and forums | P3: commercial | Q3: Organic
A4: wooden corner shelf | B4: 3 | C4: 5 | D4: 1300 | E4: 18 | F4: 0,44 | G4: https://www.spryinterior.com/collections/corner-floating-shelves | H4: 57 | I4: 3,92 | J4: 25 | K4: 0,79 | L4: 219 | M4: 13, 22, 43, 22, 36, 20, 20, 54, 16, 13, 13, 43 | N4: ######## | O4: Image pack, Sitelinks, Video, Video Carousel, Popular products, Related searches, Short videos | P4: commercial | Q4: Organic
A5: wall corner shelves | B5: 1 | C5: 3 | D5: 390 | E5: 34 | F5: 0,42 | G5: https://www.spryinterior.com/collections/corner-floating-shelves | H5: 51 | I5: 3,5 | J5: 21 | K5: 1 | L5: 232 | M5: 10, 6, 36, 36, 30, 36, 20, 16, 36, 20, 20, 45 | N5: ######## | O5: Image pack, Sitelinks, Video, Popular products, Related searches | P5: commercial | Q5: Organic
A6: corner wall shelf | B6: 5 | C6: 4 | D6: 5400 | E6: 41 | F6: 0,4 | G6: https://www.spryinterior.com/collections/corner-floating-shelves | H6: 48 | I6: 3,3 | J6: 19 | K6: 1 | L6: 245 | M6: 36, 36, 44, 36, 36, 44, 44, 44, 66, 44, 44, 66 | N6: ######## | O6: Image pack, Sitelinks, Video, People also ask, Popular products, Related searches, Short videos, Discussions and forums | P6: commercial | Q6: Organic
A7: corner wood shelf floating | B7: 1 | C7: 1 | D7: 320 | E7: 18 | F7: 0,54 | G7: https://www.spryinterior.com/collections/corner-floating-shelves | H7: 42 | I7: 2,89 | J7: 22 | K7: 1 | L7: 210 | M7: 44, 44, 29, 12, 19, 15, 81, 54, 5, 100, 23, 2 | N7: ######## | O7: Image pack, Sitelinks, Video, Image, Video Carousel, Popular products, Related searches | P7: commercial | Q7: Organic
A8: corner wall shelves | B8: 3 | C8: 3 | D8: 1600 | E8: 34 | F8: 0,4 | G8: https://www.spryinterior.com/collections/corner-floating-shelves | H8: 35 | I8: 2,4 | J8: 14 | K8: 1 | L8: 227 | M8: 13, 13, 36, 28, 54, 19, 28, 13, 24, 10, 28, 36 | N8: ######## | O8: Image pack, Sitelinks, Video, Popular products, Related searches, Things to know | P8: commercial | Q8: Organic
A9: wooden corner shelf floating | B9: 1 | C9: 0 | D9: 210 | E9: 15 | F9: 0,54 | G9: https://www.spryinterior.com/collections/corner-floating-shelves | H9: 27 | I9: 1,85 | J9: 14 | K9: 1 | L9: 216 | M9: 3, 8, 0, 3, 2, 1, 5, 2, 100, 2, 2, 2 | N9: ######## | O9: Image pack, Sitelinks, Video, Video Carousel, Popular products, Related searches | P9: commercial, informational | Q9: Organic
A10: corner shelving | B10: 4 | C10: 0 | D10: 2900 | E10: 41 | F10: 0,42 | G10: https://www.spryinterior.com/collections/corner-floating-shelves | H10: 26 | I10: 1,78 | J10: 10 | K10: 1 | L10: 229 | M10: 10, 13, 16, 7, 8, 8, 8, 7, 10, 8, 8, 8 | N10: ######## | O10: Image pack, Sitelinks, Video, People also ask, Popular products, Related searches, Short videos, Things to know | P10: commercial | Q10: Organic
A11: corner shelves | B11: 10 | C11: 3 | D11: 14800 | E11: 39 | F11: 0,42 | G11: https://www.spryinterior.com/collections/corner-floating-shelves | H11: 22 | I11: 1,51 | J11: 9 | K11: 1 | L11: 246 | M11: 24, 29, 36, 36, 24, 29, 44, 44, 44, 36, 36, 36 | N11: ######## | O11: Image pack, Sitelinks, Video, Image, People also ask, Popular products, Related searches, Things to know, Discussions and forums | P11: commercial, informational | Q11: Organic
A12: wall mounted corner shelves | B12: 3 | C12: 3 | D12: 480 | E12: 31 | F12: 0,41 | G12: https://www.spryinterior.com/collections/corner-floating-shelves | H12: 21 | I12: 1,44 | J12: 8 | K12: 1 | L12: 226 | M12: 5, 2, 7, 5, 66, 8, 10, 8, 79, 8, 5, 7 | N12: ######## | O12: Image pack, Sitelinks, Video, Video Carousel, Popular products, Related searches | P12: commercial | Q12: Organic
A13: corner shelves for wall | B13: 4 | C13: 4 | D13: 880 | E13: 28 | F13: 0,4 | G13: https://www.spryinterior.com/collections/corner-floating-shelves | H13: 21 | I13: 1,44 | J13: 8 | K13: 1 | L13: 246 | M13: 1, 0, 13, 5, 100, 65, 82, 82, 1, 1, 0, 3 | N13: ######## | O13: Image pack, Sitelinks, Video, People also ask, Popular products, Related searches | P13: informational | Q13: Organic
A14: wall mount corner shelf | B14: 5 | C14: 5 | D14: 880 | E14: 36 | F14: 0,4 | G14: https://www.spryinterior.com/collections/corner-floating-shelves | H14: 19 | I14: 1,3 | J14: 7 | K14: 1 | L14: 258 | M14: 0, 100, 29, 20, 2, 2, 0, 0, 0, 22, 16, 29 | N14: ######## | O14: Image pack, Sitelinks, Video, Image, People also ask, Popular products, Related searches | P14: informational | Q14: Organic
A15: wall corner shelf | B15: 4 | C15: 18 | D15: 720 | E15: 34 | F15: 0,42 | G15: https://www.spryinterior.com/collections/corner-floating-shelves | H15: 17 | I15: 1,16 | J15: 7 | K15: 1 | L15: 252 | M15: 10, 10, 18, 13, 7, 13, 13, 13, 13, 13, 13, 3 | N15: ######## | O15: Image pack, Sitelinks, Video, People also ask, Popular products, Related searches, Discussions and forums | P15: commercial | Q15: Organic
A16: shelf corner wall | B16: 4 | C16: 18 | D16: 720 | E16: 38 | F16: 0,4 | G16: https://www.spryinterior.com/collections/corner-floating-shelves | H16: 17 | I16: 1,16 | J16: 6 | K16: 1 | L16: 243 | M16: 0, 0, 0, 0, 0, 0, 0, 0, 0, 0, 100, 0 | N16: ######## | O16: Image pack, Sitelinks, Video, People also ask, Popular products, Related searches, Discussions and forums | P16: commercial | Q16: Organic
... A20: live edge corner shelf | B20: 2 | C20: 2 | D20: 320 | E20: 19 | F20: 0,59 | G20: https://www.spryinterior.com/collections/corner-floating-shelves | H20: 14 | I20: 0,96 | J20: 8 | K20: 1 | L20: 247 | M20: 66, 54, 54, 54, 66, 100, 66, 66, 81, 81, 66, 66 | N20: ######## | O20: Image pack, Sitelinks, Reviews, Video, Image, People also ask, Popular products, Related searches | P20: informational | Q20: Organic
A21: wooden corner shelves | B21: 7 | C21: 7 | D21: 720 | E21: 29 | F21: 0,44 | G21: https://www.spryinterior.com/collections/corner-floating-shelves | H21: 13 | I21: 0,89 | J21: 5 | K21: 0,79 | L21: 213 | M21: 7, 0, 37, 68, 46, 46, 46, 31, 13, 20, 20, 100 | N21: ######## | O21: Image pack, Sitelinks, Video, People also ask, Popular products, Related searches | P21: commercial | Q21: Organic
A22: living room corner shelves | B22: 2 | C22: 3 | D22: 210 | E22: 21 | F22: 0,46 | G22: https://www.spryinterior.com/collections/corner-floating-shelves | H22: 13 | I22: 0,89 | J22: 5 | K22: 1 | L22: 218 | M22: 23, 36, 19, 23, 36, 29, 44, 36, 29, 23, 36, 23 | N22: ######## | O22: Image pack, Sitelinks, Video, Popular products, Related searches, Short videos | P22: informational, transactional | Q22: Organic
A23: corner modern shelves | B23: 2 | C23: 3 | D23: 170 | E23: 25 | F23: 0,69 | G23: https://www.spryinterior.com/collections/corner-floating-shelves | H23: 13 | I23: 0,89 | J23: 8 | K23: 1 | L23: 195 | M23: 54, 54, 18, 1, 1, 5, 66, 11, 28, 44, 11, 28 | N23: ######## | O23: Sitelinks, Video, Video Carousel, Popular products, Related searches | P23: commercial | Q23: Organic
A24: corner wall mounted shelf | B24: 4 | C24: 12 | D24: 320 | E24: 31 | F24: 0,5 | G24: https://www.spryinterior.com/collections/corner-floating-shelves | H24: 11 | I24: 0,75 | J24: 5 | K24: 1 | L24: 203 | M24: 1, 1, 13, 82, 1, 1, 0, 24, 0, 0, 0, 11 | N24: ######## | O24: Image pack, Sitelinks, Video, Popular products, Related searches | P24: informational, transactional | Q24: Organic
A25: decorative corner shelves | B25: 1 | C25: 17 | D25: 140 | E25: 28 | F25: 0,41 | G25: https://www.spryinterior.com/collections/corner-floating-shelves | H25: 11 | I25: 0,75 | J25: 4 | K25: 1 | L25: 227 | M25: 81, 53, 81, 53, 34, 21, 21, 53, 28, 34, 34, 34 | N25: ######## | O25: Image pack, Sitelinks, Video, Image, Popular products, Related searches, Short videos | P25: commercial | Q25: Organic
A26: corner wall shelving | B26: 2 | C26: 2 | D26: 170 | E26: 34 | F26: 0,4 | G26: https://www.spryinterior.com/collections/corner-floating-shelves | H26: 11 | I26: 0,75 | J26: 4 | K26: 1 | L26: 225 | M26: 23, 7, 100, 12, 29, 3, 2, 12, 36, 5, 12, 12 | N26: ######## | O26: Image pack, Sitelinks, Video, People also ask, Popular products, Related searches | P26: informational | Q26: Organic
